Workbook

Sheet SC Shop Analytics
B1: SC · SHOP ANALYTICS (Key metrics)
B2: [SC] Dado oficial da conta — Seller Center. Fecha o GMV total do período.
B3: Mapa de colunas — escolha a LETRA da coluna no export; o 4D soma sozinho
B4: Métrica | C4: Coluna | D4: Resultado | E4: Cabeçalho esperado no export
B5: GMV total (R$) | D5: =IFERROR(SUM(INDIRECT(C5&"11:"&C5&"100000")),0) | E5: Some a coluna de GMV do período. Cabeçalho ~ 'GMV'.
B9: ⬇ COLE O EXPORT A PARTIR DE A10 (linha 10 = cabeçalho do arquivo · dados a partir da linha 11)

Sheet SC Product list
B1: SC · PRODUCT LIST (com atribuição)
B2: [SC] A peça-chave: dá a DECOMPOSIÇÃO real do GMV (orgânico × creator × live) e a concentração por SKU.
B3: Mapa de colunas — escolha a LETRA da coluna no export; o 4D soma sozinho
B4: Métrica | C4: Coluna | D4: Resultado | E4: Cabeçalho esperado no export
B5: GMV total atribuído (R$) | D5: =IFERROR(SUM(INDIRECT(C5&"11:"&C5&"100000")),0) | E5: Coluna 'GMV' (total por produto).
B6: GMV atribuído a CRIADOR — D3 (R$) | D6: =IFERROR(SUM(INDIRECT(C6&"11:"&C6&"100000")),0) | E6: Coluna 'GMV atribuído ao criador/afiliado'.
B7: GMV atribuído a LIVE — D4 (R$) | D7: =IFERROR(SUM(INDIRECT(C7&"11:"&C7&"100000")),0) | E7: Coluna 'GMV via LIVE' (se o export trouxer).
B8: Maior GMV de 1 produto (R$) | D8: =IFERROR(MAX(INDIRECT(C8&"11:"&C8&"100000")),0) | E8: Mesma coluna do GMV total — pega o maior SKU (concentração).
B9: ⬇ COLE O EXPORT A PARTIR DE A10 (linha 10 = cabeçalho do arquivo · dados a partir da linha 11)

Sheet SC Creator List
B1: SC · TRANSACTION — CREATOR LIST
B2: [SC] Pareto de creators (quantos, quanto cada um traz, o top).
B3: Mapa de colunas — escolha a LETRA da coluna no export; o 4D soma sozinho
B4: Métrica | C4: Coluna | D4: Resultado | E4: Cabeçalho esperado no export
B5: Nº de creators | C5: A | D5: =IFERROR(COUNTA(INDIRECT(C5&"11:"&C5&"100000")),0) | E5: Coluna do nome do creator.
B6: GMV total dos creators (R$) | D6: =IFERROR(SUM(INDIRECT(C6&"11:"&C6&"100000")),0) | E6: Coluna 'GMV' por creator.
B7: Maior GMV de 1 creator (R$) | D7: =IFERROR(MAX(INDIRECT(C7&"11:"&C7&"100000")),0) | E7: Mesma coluna de GMV — top creator (Pareto).
B9: ⬇ COLE O EXPORT A PARTIR DE A10 (linha 10 = cabeçalho do arquivo · dados a partir da linha 11)

Sheet SC affiliate_orders
B1: SC · AFFILIATE_ORDERS (.csv)
B2: [SC] Fecha o CT% real: a comissão paga por pedido de afiliado.
B3: Mapa de colunas — escolha a LETRA da coluna no export; o 4D soma sozinho
B4: Métrica | C4: Coluna | D4: Resultado | E4: Cabeçalho esperado no export
B5: Comissões de afiliados (R$) | D5: =IFERROR(SUM(INDIRECT(C5&"11:"&C5&"100000")),0) | E5: Coluna 'comissão' (R$) por pedido de afiliado.
B9: ⬇ COLE O EXPORT A PARTIR DE A10 (linha 10 = cabeçalho do arquivo · dados a partir da linha 11)

Sheet SC Sample
B1: SC · SAMPLE ANALYSIS
B2: [SC] Amostras enviadas (entram no CT% como ~6% de frete).
B3: Mapa de colunas — escolha a LETRA da coluna no export; o 4D soma sozinho
B4: Métrica | C4: Coluna | D4: Resultado | E4: Cabeçalho esperado no export
B5: Nº de amostras | C5: A | D5: =IFERROR(COUNTA(INDIRECT(C5&"11:"&C5&"100000")),0) | E5: 1 linha por amostra (conte) — ou aponte a coluna de quantidade.
B6: Custo real de amostras (R$) — opcional | D6: =IFERROR(SUM(INDIRECT(C6&"11:"&C6&"100000")),0) | E6: COGS + envio, se quiser usar o valor real.
B9: ⬇ COLE O EXPORT A PARTIR DE A10 (linha 10 = cabeçalho do arquivo · dados a partir da linha 11)

Sheet SC Ads
B1: SC · ADS MANAGER (GMV Max / Spark)
B2: [SC] Investimento e retorno de mídia. Fecha o componente de Ads no CT%.
B3: Mapa de colunas — escolha a LETRA da coluna no export; o 4D soma sozinho
B4: Métrica | C4: Coluna | D4: Resultado | E4: Cabeçalho esperado no export
B5: Investimento em Ads (R$) | D5: =IFERROR(SUM(INDIRECT(C5&"11:"&C5&"100000")),0) | E5: Coluna 'Custo' / 'Cost' do GMV Max.
B6: GMV gerado via Ads (R$) | D6: =IFERROR(SUM(INDIRECT(C6&"11:"&C6&"100000")),0) | E6: Coluna 'Receita' / 'GMV' / 'Gross revenue'.
B9: ⬇ COLE O EXPORT A PARTIR DE A10 (linha 10 = cabeçalho do arquivo · dados a partir da linha 11)

Sheet FM Produtos
B1: FM · PRODUTOS (FastMoss)
B2: [FM] Benchmark de concorrência — top produtos da categoria (kit/ticket de referência).
B3: Mapa de colunas — escolha a LETRA da coluna no export; o 4D soma sozinho
B4: Métrica | C4: Coluna | D4: Resultado | E4: Cabeçalho esperado no export
B5: Nº de produtos no export | C5: B | D5: =IFERROR(COUNTA(INDIRECT(C5&"11:"&C5&"100000")),0) | E5: FastMoss: coluna 'Product name'.
B6: Maior GMV — top produto (R$) | C6: K | D6: =IFERROR(MAX(INDIRECT(C6&"11:"&C6&"100000")),0) | E6: FastMoss: coluna 'GMV (-day)'.
B9: ⬇ COLE O EXPORT A PARTIR DE A10 (linha 10 = cabeçalho do arquivo · dados a partir da linha 11)

Sheet FM Creators
B1: FM · CREATORS (FastMoss)
B2: [FM] Benchmark — bucket de creators da categoria para outreach.
B3: Mapa de colunas — escolha a LETRA da coluna no export; o 4D soma sozinho
B4: Métrica | C4: Coluna | D4: Resultado | E4: Cabeçalho esperado no export
B5: Nº de creators no bucket | C5: A | D5: =IFERROR(COUNTA(INDIRECT(C5&"11:"&C5&"100000")),0) | E5: FastMoss: coluna 'Creator name'.
B6: Maior GMV — top creator (R$) | C6: I | D6: =IFERROR(MAX(INDIRECT(C6&"11:"&C6&"100000")),0) | E6: FastMoss: coluna 'GMV'.
B9: ⬇ COLE O EXPORT A PARTIR DE A10 (linha 10 = cabeçalho do arquivo · dados a partir da linha 11)

Sheet Resumo Exports
B1: RESUMO DOS EXPORTS · o 4D lê daqui
B2: Preenche sozinho ao colar os exports nas abas SC/FM. Alimenta a Entrada e a Classificação.
B3: GMV
B4: GMV total (R$) | C4: =IF('SC Product list'!D5>0,'SC Product list'!D5,'SC Shop Analytics'!D5) | D4: Product list (se tiver); senão Shop Analytics.
B5: GMV D3 — creator/afiliados (R$) | C5: ='SC Product list'!D6
B6: GMV D4 — live (R$) | C6: ='SC Product list'!D7
B7: GMV D1 — orgânico/loja (R$) | C7: =MAX(C4-C5-C6,0) | D7: =total − creator − live.
B8: Concentração do maior SKU (%) | C8: =IFERROR('SC Product list'!D8/C4,"") | D8: Risco se 1 SKU puxa 50%+.
B9: % do GMV via D3 (creator) | C9: =IFERROR(C5/C4,"")
B10: % do GMV via D4 (live) | C10: =IFERROR(C6/C4,"")
B11: % do GMV via D1 (orgânico) | C11: =IFERROR(C7/C4,"")
B13: CT% — componentes
B14: Comissões de afiliados (R$) | C14: ='SC affiliate_orders'!D5
B15: Nº de amostras | C15: ='SC Sample'!D5
B16: Custo real de amostras (R$, opcional) | C16: ='SC Sample'!D6
B17: Só o custo de lives não tem export (cachê interno) — digite na aba Entrada (C15).
B19: D3 — Pareto de creators
B20: Nº de creators (conta) | C20: ='SC Creator List'!D5
B21: Top creator — % do GMV de creators | C21: =IFERROR('SC Creator List'!D7/'SC Creator List'!D6,"") | D21: Concentração em 1 creator.
B23: FM — benchmark (concorrência)
B24: Top produto concorrente — GMV (R$) | C24: ='FM Produtos'!D6
B25: Top creator da categoria — GMV (R$) | C25: ='FM Creators'!D6
B27: Ads (do export SC Ads)
B28: Investimento em Ads (R$) | C28: ='SC Ads'!D5
B29: GMV gerado via Ads (R$) | C29: ='SC Ads'!D6
B30: ROAS (GMV Ads ÷ investimento) | C30: =IFERROR(C29/C28,"") | D30: ≥ mínimo da margem; 10x é ótimo.

Sheet Entrada
B1: CALCULADORA ELEVATE 4D · ENTRADA
B2: Cole os exports nas abas SC/FM → GMV, Ads, comissões e amostras vêm sozinhos (verde). Só o custo de lives e as notas 0–5 você preenche (amarelo). A aba 'Classificação' calcula tudo.
B3: 1. CONTEXTO (define o momento)
B4: Cliente / categoria | D4: texto livre
B5: Loja TikTok aprovada e vendendo? | D5: Sim / Não
B6: Tem produto-tração (hero) claro? | D6: Sim / Não
B7: Tendência do GMV | D7: Crescendo / Estável / Caindo
B8: Nº de dimensões ATIVAS (0–4) | D8: pernas que puxam GMV de forma relevante (não só existem)
B9: Nº de dimensões MADURAS (0–4) | D9: pernas já fortes/maduras (nota ≥ 4)
B11: 2. FINANCEIRO (define o CT%)
B12: GMV total no período | C12: =IF('Resumo Exports'!C4=0,"",'Resumo Exports'!C4) | D12: AUTO: vem do Resumo (Product list / Shop Analytics). Pode digitar por cima.
B13: Investimento em Ads | C13: =IF('Resumo Exports'!C28=0,"",'Resumo Exports'!C28) | D13: AUTO: aba SC Ads (investimento). Pode digitar por cima.
B14: Comissões de afiliados pagas | C14: =IF('Resumo Exports'!C14=0,"",'Resumo Exports'!C14) | D14: AUTO: soma de affiliate_orders. Pode digitar por cima.
B15: Custo de lives (host/apresentadora) | D15: R$
B16: Nº de amostras grátis enviadas | C16: =IF('Resumo Exports'!C15=0,"",'Resumo Exports'!C15) | D16: AUTO: aba SC Sample. Pode digitar por cima.
B17: Valor nominal médio do produto | D17: R$ (preço cheio do SKU)
B18: Taxa de amostra da plataforma | C18: 0.06 | D18: padrão 6%
B19: Custo de amostras (automático) | C19: =C16*C17*C18 | D19: =nº amostras × valor nominal × 6% (taxa, não frete)
B20: Saldo de settlement (opcional) | D20: R$ — negativo = caixa drenado
B22: 3. NOTAS POR DIMENSÃO (0–5 cada sub-critério)
B23: Régua: 0 inexistente · 1 iniciando · 2 fraco · 3 ok · 4 forte · 5 referência
B24: D1 — Produtos
B25: Sortimento / hero (heroes + cauda equilibrada) | C25: 0
B26: Ticket / lidera com kit | C26: 0
B27: Margem de contribuição cobre o CT% | C27: 0
B28: Listing completo + avaliações ≥ 4,7 | C28: 0
B29: Estoque sem ruptura nos campeões + SLAs | C29: 0
B30: D2 — Ads
B31: Conta / estrutura de campanha ativa | C31: 0
B32: ROI / ROAS saudável (≥ mín. da margem; 10x ótimo) | C32: 0
B33: CT% de Ads sob controle | C33: 0
B34: Verba concentrada em heroes + Spark Ads | C34: 0
B35: D3 — Afiliados
B36: Massa de creators ativos | C36: 0
B37: Outreach sistemático | C37: 0
B38: Comissão competitiva + incentivos | C38: 0
B39: Programa de amostras (escala) | C39: 0
B40: Feedback / orientação aos creators | C40: 0
B41: Pareto identificado + retenção | C41: 0
B42: D4 — Social
...

Sheet Classificação
A1: CLASSIFICAÇÃO ELEVATE 4D
A3: Momento | B3: =B4&" — "&VLOOKUP(B4,$A$21:$F$27,6,FALSE)
B4: =IF(Entrada!C5="Não","M0",IF(Entrada!C6="Não","M1",IF(Entrada!C7="Caindo","M5",IF(Entrada!C7="Estável",IF(Entrada!C9>=2,"M6","M4"),IF(Entrada!C8<=1,"M2","M3")))))
A5: CT% | B5: =IFERROR((Entrada!C13+Entrada!C14+Entrada!C15+Entrada!C19)/Entrada!C12,"") | C5: =IF(B5="","faltam dados de GMV/custos",IF(B5<=0.2,"🟢 Saudável",IF(B5<=0.35,"🟡 Atenção","🔴 Crítico (compra o próprio GMV)")))
A7: Dimensão | B7: Nota (0–5) | C7: Baseline | D7: Gap | E7: Status
A8: D1 Produtos | B8: =AVERAGE(Entrada!C25:C29) | C8: =VLOOKUP($B$4,$A$21:$F$27,2,FALSE) | D8: =C8-B8 | E8: =IF(D8<=0,"✓ ok/acima",IF(D8>=1.5,"🔴 crítico","🟡 abaixo"))
A9: D2 Ads | B9: =AVERAGE(Entrada!C31:C34) | C9: =VLOOKUP($B$4,$A$21:$F$27,3,FALSE) | D9: =C9-B9 | E9: =IF(D9<=0,"✓ ok/acima",IF(D9>=1.5,"🔴 crítico","🟡 abaixo"))
A10: D3 Afiliados | B10: =AVERAGE(Entrada!C36:C41) | C10: =VLOOKUP($B$4,$A$21:$F$27,4,FALSE) | D10: =C10-B10 | E10: =IF(D10<=0,"✓ ok/acima",IF(D10>=1.5,"🔴 crítico","🟡 abaixo"))
A11: D4 Social | B11: =AVERAGE(Entrada!C43:C47) | C11: =VLOOKUP($B$4,$A$21:$F$27,5,FALSE) | D11: =C11-B11 | E11: =IF(D11<=0,"✓ ok/acima",IF(D11>=1.5,"🔴 crítico","🟡 abaixo"))
A13: Dimensão prioritária | B13: =IF(MAX(D8:D11)<=0,"D1 Produtos — sem dimensão abaixo do baseline; otimizar a partir do chão (margem/LTV)",IF(D8=MAX(D8:D11),"D1 Produtos — o chão; corrigir antes das outras",IF(D10=MAX(D8:D11),"D3 Afiliados — o motor distribuído",IF(D11=MAX(D8:D11),"D4 Social — marca + recorrência","D2 Ads — acelerador"))))
A15: Regra: dimensão fraca só é prioridade se o momento já a exigia forte. Empate → D1>D3>D4>D2.
A16: Decomposição do GMV (dos exports) | B16: preenche ao colar o Product list (Resumo Exports)
A17: D1 orgânico % | B17: =IFERROR('Resumo Exports'!C11,"") | C17: D3 afiliados % | D17: =IFERROR('Resumo Exports'!C9,"") | E17: D4 live % | F17: =IFERROR('Resumo Exports'!C10,"")
A18: Concentração maior SKU | B18: =IFERROR('Resumo Exports'!C8,"") | C18: Top creator % (Pareto) | D18: =IFERROR('Resumo Exports'!C21,"")
A19: (tabela de baseline por momento — não editar)
A20: Cód | B20: D1 | C20: D2 | D20: D3 | E20: D4 | F20: Nome
A21: M0 | B21: 3 | C21: 0 | D21: 0.5 | E21: 1 | F21: Probatório
A22: M1 | B22: 3.5 | C22: 1 | D22: 2 | E22: 2 | F22: Lançamento
A23: M2 | B23: 4 | C23: 2 | D23: 3 | E23: 2.5 | F23: Tração inicial
A24: M3 | B24: 4 | C24: 3.5 | D24: 4 | E24: 3 | F24: Escala
A25: M4 | B25: 4 | C25: 4 | D25: 4 | E25: 3.5 | F25: Platô
A26: M5 | B26: 4 | C26: 3 | D26: 3.5 | E26: 3 | F26: Crise/Queda
A27: M6 | B27: 5 | C27: 4 | D27: 4.5 | E27: 4 | F27: Maturidade
